################################################################################
2015-07-31 18:16:47,295 ERROR: Exception on /results_clustered [POST]
Traceback (most recent call last):
  File "/Library/Python/2.7/site-packages/flask/app.py", line 1817, in wsgi_app
    response = self.full_dispatch_request()
  File "/Library/Python/2.7/site-packages/flask/app.py", line 1477, in full_dispatch_request
    rv = self.handle_user_exception(e)
  File "/Library/Python/2.7/site-packages/flask/app.py", line 1381, in handle_user_exception
    reraise(exc_type, exc_value, tb)
  File "/Library/Python/2.7/site-packages/flask/app.py", line 1475, in full_dispatch_request
    rv = self.dispatch_request()
  File "/Library/Python/2.7/site-packages/flask/app.py", line 1461, in dispatch_request
    return self.view_functions[rule.endpoint](**req.view_args)
  File "runserver.py", line 547, in results_clustered
    header, results = read_results_file(fn_results_orig_absolute)
  File "runserver.py", line 342, in read_results_file
    with open(fn, 'r') as fh:
IOError: [Errno 2] No such file or directory: u'/Users/dblyon/modules/cpr/goterm/agotool/static/data/session/results_origd.tsv'
